# Tratamento de Exceções

## Definição

 São tentativas de prever erros que podem ocorrer durante a criação de um programa no Java, que vem de erros lógicos ou problemas externos.
 Se utilizam os comandos "try" e "catch" como forma de "prever" os erros.

## Exceções comuns

### Divisão por zero

     public class Main {
     public static void main(String[] args) {
	try{
		int num1 = 2;
		int num2 = 0;
		int operacao = num1/num2;
		System.out.println("Divisão");
	}catch (ArithmeticException e){
		System.out.println("Divisão por zero");
	}catch (Exception e){
           e.printStackTrace();
        }
      }

### Conversão de tipos de dados inválidos

public class Main {
     public static void main(String[] args) {
	try{
		Object objeto = new Object();
		String string = (String) o;
	} catch (Exception e) {
		System.out.println("Não é possível a conversão"); 
	}
	}

### Acessar uma posição inválida em um arranjo

     public class Main {
     public static void main(String[] args) {
	try{
	     ArrayList<Integer> l = new ArrayList<>();
	     l.get(99)
	}catch (IndexOutOfBoundsException e){
	  System.out.println(Erro);
	  }

### Acessar uma String nula

public class Main {
      public static void main(String[] args) {
	try{
		String string = null
		string.replace ("","")
		System.out.println("Substituida a String");
	}catch (NullPointerException e){
		System.out.println("String null");
	}catch (Exception e){
           e.printStackTrace();
        }
      }

## Bloco para capturar uma exceção

 Se utilliza o bloco "catch", junto com o nome da exceção para capturar uma exceção em especifico
      Exemplo:
      }catch (ArithmeticException e){

## Bloco para capturar diferentes exceções

Para se tratar de multiplas exceções diferentes, deve-se criar diversos comandos de catch
 Exemplo:
      try{
   String = null
   s.replace("","")
  int num1 = 2;
		int num2 = 0;
		int operacao = num1/num2;
		System.out.println("Divisão");
  }catch(ArithmeticException e){
     System.out.println("dividido por zero");
  }catch(NullPointerException e){
     System.out.println("String null");
   }
  }


## Bloco finally

É executado após o bloco try, independentemente de sua conclusão, estando em execução ou interrompido.
     public class Main {
     public static void main(String[] args) {
	try{
		int num1 = 5;
		int num2 = 0;
		int operacao = num1/num2;
		System.out.println("Depois da Divisão");
	}catch (ArithmeticException e){
		System.out.println("Divisão por zero");
	}catch (Exception e){
           e.printStackTrace();
            }
	finally {
	  System.out.println("Encerrou o processo")
         	}
	}

## Lançar uma exceção

public class Main {
public static void main(String[] args)
 throws Exception{
  throw new Exception("Exceção");
  }
 }
